Workbook

Sheet REMARK CAP
B2: CAP untuk Coating, Visual, dan Function (C/V/F) Konstruksi, Lambung/Plat, Peralatan deck, Permesinan Kapal dan Permesinan Geladak
B4: CATEGORY | C4: CRITERIA/ITEM | D4: CAP SCORE
D5: 1 | E5: 2 | F5: 3 | G5: 4
B6: C | C6: Kondisi Pelapisan/Cat pada Konstruksi, Plat, Perpipaan dan Peralatan deck lainnya | D6: Tidak terdapat lapisan pelindung | E6: Lapisan pelindung tidak terawat | F6: Lapisan pelindung terawat | G6: Lapisan pelindung dalam kondisi baru
B8: V | C8: Kondisi Retak/Crack dan Deformasi pada Konstruksi, Perpipaan, Plat dan Peralatan deck lainnya | D8: Terdapat kerusakan peralatan,perpipaan, crack dan deformasi yang signifikan | E8: Terdapat spot crack, deformasi serta kerusakan peralatan dan perpipaan | F8: Terdapat area crack, deformasi dan kerusakan peralatan, perpipaan tingkat rendah | G8: Tidak terdapat kerusakan peralatan, perpipaan ataupun crack dan deformasi pada spot area sesuai dengan kondisi baru
C9: Kondisi Ruang-ruangan Kapal
C10: Kondisi Sistim Permesinan Kapal & Permesinan Geladak | D10: Terdapat kerusakan secara signifikan | E10: Terdapat spot kerusakan pada item dan komponen | F10: Terdapat kerusakan pada item dan komponen tingkat rendah | G10: Tidak terdapat kerusakan item dan komponen serta dalam kondisi baru
C11: Kondisi Alat Navigasi dan Komunikasi | D11: Terdapat kerusakan fisik secara signifikan | E11: Terdapat kerusakan fisik dan komponen peralatan | F11: Tidak terdapat kerusakan fisik dan terawat | G11: Kondisi fisik baik dan dalam kondisi baru
C12: Kondisi Life-Saving Appliances (LSA) & Fire-Fighting Appliances (FFA) | D12: Terdapat kerusakan secara signifikan | E12: Terdapat spot kerusakan fisik dan komponen peralatan | F12: Tidak terdapat kerusakan dan terawat | G12: Kondisi fisik baik dan dalam kondisi baru
B14: F | C14: Sistim Permesinan Kapal dan Permesinan Geladak | D14: Terdapat kerusakan komponen secara signifikan dan tidak berfungsi | E14: Terdapat spot kerusakan pada komponen permesinan | F14: Terdapat penurunan peforma pada komponen permesinan dan berfungsi | G14: Berfungsi dengan baik sesuai dengan kondisi baru
C15: Sistim Kumpa-Kumpa (Pompa) | D15: Terdapat kerusakan pada item dan komponen secara signifikan dan tidak berfungsi | E15: Terdapat kerusakan pada item dan komponen | F15: Berfungsi dan terdapat penurunan peforma | G15: Berfungsi dengan baik sesuai dengan kondisi baru
C16: Alat Navigasi dan Komunikasi | D16: Tidak berfungsi dan terdapat kerusakan secara signifikan | E16: Tidak berfungsi secara optimal dan terdapat kerusakan komponen peralatan | F16: Berfungsi secara optimal dan terdapat penurunan peforma | G16: Berfungsi dengan baik sesuai dengan kondisi baru
B17: Keterangan : C (Coating) ; V (Visual) ; F (Function)
B20: CAP untuk Maintenance (M) Dokumen Kapal, Life-Saving Appliances (LSA) & Fire-Fighting Appliances (FFA)
B22: CATEGORY | C22: CRITERIA/ITEM | D22: CAP SCORE
D23: 1 | E23: 2 | F23: 3 | G23: 4
B24: M | C24: Dokumen Kapal | D24: Sertifikat telah melewati masa berlaku | E24: Masa berlaku sertifikat sisa 1 bulan mendekati tanggal masa berlaku | F24: Masa berlaku sertifikat sisa 3 bulan mendekati tanggal masa berlaku | G24: Masa berlaku sertifikat masih aktif
D25: Semua sertifikat fisik dan dokumen dalam bentuk hard copy / soft copy tidak ada. | E25: Semua sertifikat fisik dan dokumen dalam hard / soft copy wajib ada di atas kapal
C26: Life-Saving Appliances (LSA) & Fire-Fighting Appliances (FFA) | D26: Memiliki masa berlaku sudah expired | E26: Memiliki masa berlaku mendekati 1 bulan dari tanggal expired | F26: Memiliki masa berlaku mendekati 3 bulan dari tanggal expired | G26: Memiliki masa berlaku lebih dari 3 bulan dari tanggal expired

Sheet curve
B1: Nama Kapal | C1: TAHUN | E1: CAP | F1: CAP | G1: CAP | H1: CAP | I1: CAP | J1: CAP | K1: CAP | L1: CAP
O3: Umur Kapal | P3: CAP Kapal
A4: 1 | B4: KMP. PORTLINK V | C4: 2011 | D4: =2026-C4 -> 15 | E4: 3.64 | F4: 3.02 | G4: 2.98 | H4: 3.02 | I4: 3.14 | J4: 3.13 | K4: 2.9 | L4: 2.93 | M4: =AVERAGE(E4:L4) -> 3.095 | O4: 5 | P4: =AVERAGE('EXECUTIVE SUMMARY (2)'!H6,'EXECUTIVE SUMMARY (2)'!H10,'EXECUTIVE SUMMARY (2)'!H18,'EXECUTIVE SUMMARY (2)'!H22,'EXECUTIVE SUMMARY (2)'!O6,'EXECUTIVE SUMMARY (2)'!O14,'EXECUTIVE SUMMARY (2)'!O20) -> 4
A5: 2 | B5: KMP. JATRA III | C5: 1985 | D5: =2026-C5 -> 41 | E5: 4 | F5: 2.95 | G5: 3 | H5: 2.98 | I5: 3 | J5: 3.36 | K5: 3 | L5: 3.26 | M5: =AVERAGE(E5:L5) -> 3.19375
A6: 3 | B6: KMP. FERRINDO - 5 | C6: 1986 | D6: =2026-C6 -> 40 | E6: 3.78 | F6: 2.49 | G6: 2.84 | H6: 2.54 | I6: 3 | J6: 2.81 | K6: 3 | L6: 2.9 | M6: =AVERAGE(E6:L6) -> 2.92
A7: 4 | B7: KMP. BATU MANDI | C7: 2013 | D7: =2026-C7 -> 13 | E7: 3.57 | F7: 2.96 | G7: 2.99 | H7: 2.85 | I7: 3.36 | J7: 3.12 | K7: 2.81 | L7: 3.37 | M7: =AVERAGE(E7:L7) -> 3.12875
A8: 5 | B8: KMP. SEBUKU | C8: 2013 | D8: =2026-C8 -> 13 | E8: 4 | F8: 2.94 | G8: 3 | H8: 2.96 | I8: 3 | J8: 3.32 | K8: 2.97 | L8: 3.26 | M8: =AVERAGE(E8:L8) -> 3.18125
A9: 6 | B9: KMP. LEGUNDI | C9: 2013 | D9: =2026-C9 -> 13 | E9: 3.14 | F9: 3.04 | G9: 3 | H9: 3.07 | I9: 3.25 | J9: 3.15 | K9: 2.92 | L9: 3.2 | M9: =AVERAGE(E9:L9) -> 3.09625
A10: 7 | B10: KMP. PORTLINK | C10: 1981 | D10: =2026-C10 -> 45 | E10: 3.07 | F10: 2.53 | G10: 2.82 | H10: 2.7 | I10: 2.8 | J10: 2.91 | K10: 2.68 | L10: 2.44 | M10: =AVERAGE(E10:L10) -> 2.74375
A11: 8 | B11: KMP. PORT LINK III | C11: 1986 | D11: =2026-C11 -> 40 | E11: 3.57 | F11: 2.67 | G11: 2.84 | H11: 2.92 | I11: 2.8 | J11: 2.89 | K11: 2.85 | L11: 2.94 | M11: =AVERAGE(E11:L11) -> 2.935
A12: 9 | B12: KMP. GORARE | C12: 1991 | D12: =2026-C12 -> 35 | E12: 2.93 | F12: 3 | G12: 2.58 | H12: 2.57 | I12: 2.32 | J12: 2.96 | K12: 2.95 | L12: 3 | M12: =AVERAGE(E12:L12) -> 2.78875
A13: 10 | B13: KMP. PUTERI LEANPURI | C13: 2019 | D13: =2026-C13 -> 7 | E13: 3 | F13: 3 | G13: 3 | H13: 3 | I13: 3 | J13: 3 | K13: 3.12 | L13: 3 | M13: =AVERAGE(E13:L13) -> 3.015
A14: 11 | B14: KMP. KUALA BATE - II | C14: 1992 | D14: =2026-C14 -> 34 | E14: 3 | F14: 2.67 | G14: 2.47 | H14: 2.42 | I14: 2.9 | J14: 2.53 | K14: 2.38 | L14: 2.83 | M14: =AVERAGE(E14:L14) -> 2.65
A15: 12 | B15: KMP. MUTIS | C15: 1992 | D15: =2026-C15 -> 34 | E15: 2.71 | F15: 2.96 | G15: 2.94 | H15: 2.72 | I15: 2.75 | J15: 2.83 | K15: 2.27 | L15: 2.85 | M15: =AVERAGE(E15:L15) -> 2.75375
A16: 13 | B16: KMP. MENUMBING RAYA | C16: 2010 | D16: =2026-C16 -> 16 | E16: 3.14 | F16: 2.53 | G16: 2.68 | H16: 2.51 | I16: 2.75 | J16: 3.04 | K16: 2.17 | L16: 2.8 | M16: =AVERAGE(E16:L16) -> 2.7025
... A161: 160 | B161: KMP. BILI | C161: 1990 | D161: =2026-C161 -> 36 | E161: 3.21 | F161: 2.48 | G161: 2.84 | H161: 2.51 | I161: 2.8 | J161: 2.56 | K161: 2.77 | L161: 2.69 | M161: =AVERAGE(E161:L161) -> 2.7325
B162: ADHI SWADHARMA III | C162: 1985 | D162: =2026-C162 -> 41 | E162: 3 | F162: 2.76 | G162: 2.62 | H162: 2.62 | I162: 2.35 | J162: 2.74 | K162: 2.81 | L162: 3 | M162: =AVERAGE(E162:L162) -> 2.7375
B163: ANDHIKA NUSANTARA | C163: 1999 | D163: =2026-C163 -> 27 | E163: 3.29 | F163: 2.24 | G163: 2.54 | H163: 2.28 | I163: 2.4 | J163: 2.76 | K163: 2.98 | L163: 2.83 | M163: =AVERAGE(E163:L163) -> 2.665
B164: BAHARI NUSANTARA | C164: 1969 | D164: =2026-C164 -> 57 | E164: 2.86 | F164: 3 | G164: 2.85 | H164: 2.78 | I164: 2.82 | J164: 2.97 | K164: 2.98 | L164: 2.93 | M164: =AVERAGE(E164:L164) -> 2.89875
B165: CITRA MANDALA ABADI | C165: 1971 | D165: =2026-C165 -> 55 | E165: 2.929 | F165: 2.528 | G165: 2.529 | H165: 2.389 | I165: 2.6 | J165: 3 | K165: 3 | L165: 3.079 | M165: =AVERAGE(E165:L165) -> 2.75675
B166: CITRA MANDALA SAKTI | C166: 1967 | D166: =2026-C166 -> 59 | E166: 3.2 | F166: 2.6 | G166: 2.81 | H166: 2.63 | I166: 2.43 | J166: 2.77 | K166: 2.83 | L166: 3.18 | M166: =AVERAGE(E166:L166) -> 2.80625
B167: CITRA NUSANTARA | C167: 1992 | D167: =2026-C167 -> 34 | E167: 2.71 | F167: 2.08 | G167: 2.34 | H167: 2.17 | I167: 2 | J167: 2.77 | K167: 2.83 | L167: 2.73 | M167: =AVERAGE(E167:L167) -> 2.45375
B168: FARINA NUSANTARA | C168: 1990 | D168: =2026-C168 -> 36 | E168: 2.64 | F168: 2.09 | G168: 2.93 | H168: 2.33 | I168: 2.3 | J168: 2.61 | K168: 2.91 | L168: 3.47 | M168: =AVERAGE(E168:L168) -> 2.66
B169: GADING NUSANTARA | C169: 1992 | D169: =2026-C169 -> 34 | E169: 2.43 | F169: 2.06 | G169: 2.33 | H169: 1.45 | I169: 1.5 | J169: 1.69 | K169: 2.56 | L169: 2.47 | M169: =AVERAGE(E169:L169) -> 2.06125
B170: JEMBATAN KAPUAS | C170: 1990 | D170: =2026-C170 -> 36 | E170: 3.29 | F170: 2.5 | G170: 2.84 | H170: 2.58 | I170: 2.83 | J170: 2.82 | K170: 2.83 | L170: 3.16 | M170: =AVERAGE(E170:L170) -> 2.85625
B171: JEMBATAN MUSI I | C171: 1972 | D171: =2026-C171 -> 54 | E171: 3.14 | F171: 2.62 | G171: 2.64 | H171: 2.43 | I171: 2.65 | J171: 2.68 | K171: 2.98 | L171: 2.94 | M171: =AVERAGE(E171:L171) -> 2.76
B172: JEMBATAN MUSI II | C172: 1967 | D172: =2026-C172 -> 59 | E172: 3.71 | F172: 2.8 | G172: 2.47 | H172: 2.65 | I172: 2.89 | J172: 2.67 | K172: 3 | L172: 3.2 | M172: =AVERAGE(E172:L172) -> 2.92375
B173: KALEBI | C173: 1966 | D173: =2026-C173 -> 60 | E173: 1.86 | F173: 3 | G173: 3 | H173: 2.94 | I173: 2.95 | J173: 2.72 | K173: 2.88 | L173: 3.21 | M173: =AVERAGE(E173:L173) -> 2.82
... B214: TITIAN NUSANTARA | C214: 1990 | D214: =2026-C214 -> 36 | E214: 3 | F214: 2.23 | G214: 2.11 | H214: 2.39 | I214: 2.48 | J214: 2.88 | K214: 2.55 | L214: 2.68 | M214: =AVERAGE(E214:L214) -> 2.54

Sheet EXECUTIVE SUMMARY
B3: 1
C18: Grafik ini membandingkan nilai CAP dan umur kapal terhadap kapal KMP CUCUT dengan data kapal sejenis yang telah disurvey oleh BKI.
J19: KMP CUCUT
J20: Data Kapal Pembanding
B23: 2 | C23: CONDITION | G23: =AVERAGE(G28,G32,G40,G44,N28,N36,N42) -> #REF!
D25: CAP
D26: 1 | E26: 2 | F26: 3 | G26: 4
C28: ='Hull & Cons'!B2 -> HULL & CONSTRUCTION OVERALL CAP RATING | G28: ='Hull & Cons'!H2 -> 4 | I28: =#REF! -> #REF! | N28: =#REF! -> #REF!
D29: ='Hull & Cons'!B4 -> Hull | F29: 1 | J29: =#REF! -> #REF! | M29: =#REF! -> #REF!
D30: ='Hull & Cons'!B34 -> Construction | F30: ='Hull & Cons'!H34 -> 4 | J30: =#REF! -> #REF! | M30: =#REF! -> #REF!
J31: =#REF! -> #REF! | M31: =#REF! -> #REF!
C32: =Ramp!B2 -> RAMP | G32: =Ramp!H2 -> 4 | J32: =#REF! -> #REF! | M32: =#REF! -> #REF!
D33: =Ramp!B4 -> Fore Ramp | F33: =Ramp!H4 -> 4 | J33: ='PUMP&PIPE - xx'!B3 -> Pump | M33: ='PUMP&PIPE - xx'!I3 -> 2.5
D34: =Ramp!B28 -> Bow Visor | F34: =Ramp!H28 -> 4 | J34: ='PUMP&PIPE - xx'!B42 -> Pipe | M34: ='PUMP&PIPE - xx'!I42 -> 1
D35: =Ramp!B47 -> Aft Ramp | F35: =Ramp!H47 -> 4
D36: =Ramp!B71 -> Portside Ramp | F36: =Ramp!H71 -> 4 | I36: ='BRIDGE & NAVIGATION'!B2 -> BRIDGE & NAVIGATION ROOM | N36: ='BRIDGE & NAVIGATION'!H2 -> 4
D37: =Ramp!B95 -> Starboard Ramp | F37: =Ramp!H95 -> 4 | J37: ='BRIDGE & NAVIGATION'!B4 -> General Condition | M37: ='BRIDGE & NAVIGATION'!H4 -> 4
D38: =Ramp!B119 -> In Ramp | F38: =Ramp!H119 -> 4 | J38: ='BRIDGE & NAVIGATION'!B50 -> Navigation Equipment | M38: ='BRIDGE & NAVIGATION'!H50 -> 4
J39: ='BRIDGE & NAVIGATION'!B73 -> Communication Equipment | M39: ='BRIDGE & NAVIGATION'!H73 -> 4
C40: =Accomodation!B2 -> ACCOMODATION | G40: =Accomodation!H2 -> 4 | J40: ='BRIDGE & NAVIGATION'!B90 -> Navigation Light | M40: ='BRIDGE & NAVIGATION'!H90 -> 4
D41: =Accomodation!B4 -> Crew | F41: =Accomodation!H4 -> 4
D42: =Accomodation!B41 -> Passenger | F42: =Accomodation!H41 -> 4 | I42: ='SHIP SAFETY OPERATION'!B2 -> SHIP SAFETY OPERATION | N42: ='SHIP SAFETY OPERATION'!H2 -> 4
J43: ='SHIP SAFETY OPERATION'!B4 -> Operation Document | M43: ='SHIP SAFETY OPERATION'!H4 -> 4
C44: =#REF! -> #REF! | G44: =#REF! -> #REF! | J44: ='SHIP SAFETY OPERATION'!B54 -> Life Saving Appliance | M44: ='SHIP SAFETY OPERATION'!H54 -> 2.1555556
D45: =#REF! -> #REF! | F45: =#REF! -> #REF! | J45: ='SHIP SAFETY OPERATION'!B153 -> Fire Fighting Appliance | M45: ='SHIP SAFETY OPERATION'!H153 -> 4
D46: =#REF! -> #REF! | F46: =#REF! -> #REF!

Sheet EXECUTIVE SUMMARY (2)
C3: Overall CAP Rating Breakdown
C4: Overall CAP Rating Condition EXAMPLE | N4: : | O4: =AVERAGE(H6,H10,H18,H22,O6,O14,O20) -> 4
C6: 1. Hull & Construction | G6: : | H6: ='Hull & Cons'!H2 -> 4 | J6: 5. Engine Room & Machinery | N6: : | O6: ='ER&Machinery-1'!H2 -> 4
C7: - | D7: ='Hull & Cons'!B4 -> Hull | F7: ='Hull & Cons'!H4 -> 4 | J7: - | K7: ='ER&Machinery-1'!B4 -> General Condition | M7: ='ER&Machinery-1'!H4 -> 4
C8: - | D8: ='Hull & Cons'!B34 -> Construction | F8: ='Hull & Cons'!H34 -> 4 | J8: - | K8: ='ER&Machinery-1'!B66 -> Main Engine | M8: ='ER&Machinery-1'!H66 -> 4
J9: - | K9: ='ER&Machinery-1'!B110 -> Auxiliary Engine | M9: ='ER&Machinery-1'!H110 -> 4
C10: 2. Ramp | G10: : | H10: =Ramp!H2 -> 4 | J10: - | K10: ='ER&Machinery-1'!B154 -> Generator | M10: ='ER&Machinery-1'!H154 -> 4
C11: - | D11: =Ramp!B4 -> Fore Ramp | F11: =Ramp!H4 -> 4 | J11: - | K11: ='ER&MAchinery-2'!B3 -> Pump | M11: ='ER&MAchinery-2'!I3 -> 4
C12: - | D12: =Ramp!B28 -> Bow Visor | F12: =Ramp!H28 -> 4 | J12: - | K12: ='ER&MAchinery-2'!B43 -> Pipe | M12: ='ER&MAchinery-2'!I43 -> 4
C13: - | D13: =Ramp!B47 -> Aft Ramp | F13: =Ramp!H47 -> 4
C14: - | D14: =Ramp!B71 -> Portside Ramp | F14: =Ramp!H71 -> 4 | J14: 6. Bride & Navigation | N14: : | O14: ='BRIDGE & NAVIGATION'!H2 -> 4
C15: - | D15: =Ramp!B95 -> Starboard Ramp | F15: =Ramp!H95 -> 4 | J15: - | K15: ='BRIDGE & NAVIGATION'!B4 -> General Condition | M15: ='BRIDGE & NAVIGATION'!H4 -> 4
C16: - | D16: =Ramp!B119 -> In Ramp | F16: =Ramp!H119 -> 4 | J16: - | K16: ='BRIDGE & NAVIGATION'!B50 -> Navigation Equipment | M16: ='BRIDGE & NAVIGATION'!H50 -> 4
J17: - | K17: ='BRIDGE & NAVIGATION'!B73 -> Communication Equipment | M17: ='BRIDGE & NAVIGATION'!H73 -> 4
C18: 3. Accomodation | G18: : | H18: =Accomodation!H2 -> 4 | J18: - | K18: ='BRIDGE & NAVIGATION'!B90 -> Navigation Light | M18: ='BRIDGE & NAVIGATION'!H90 -> 4
C19: - | D19: =Accomodation!B4 -> Crew | F19: =Accomodation!H4 -> 4
C20: - | D20: =Accomodation!B41 -> Passenger | F20: =Accomodation!H41 -> 4 | J20: 7. Ship Safety & Operation | N20: : | O20: ='SHIP SAFETY OPERATION'!H2 -> 4
J21: - | K21: ='SHIP SAFETY OPERATION'!B4 -> Operation Document | M21: ='SHIP SAFETY OPERATION'!H4 -> 4
C22: 4. Deck Machinery & Outfitting | G22: : | H22: ='Deck Machinery & Outfitting'!H2 -> 4 | J22: - | K22: ='SHIP SAFETY OPERATION'!B54 -> Life Saving Appliance | M22: ='SHIP SAFETY OPERATION'!H54 -> 2.1555556
C23: - | D23: ='Deck Machinery & Outfitting'!B4 -> Deck Machinery | F23: ='Deck Machinery & Outfitting'!H4 -> 4 | J23: - | K23: ='SHIP SAFETY OPERATION'!B153 -> Fire Fighting Appliance | M23: ='SHIP SAFETY OPERATION'!H153 -> 4
C24: - | D24: ='Deck Machinery & Outfitting'!B83 -> Outfitting | F24: ='Deck Machinery & Outfitting'!H83 -> 4

Sheet EXECUTIVE SUMMARY - 4
C2: Breakdown Overall Rating
C4: 1. | D4: ='Hull & Cons'!B2 -> HULL & CONSTRUCTION OVERALL CAP RATING | H4: : | I4: ='Hull & Cons'!H2 -> 4 | K4: 5. | L4: =#REF! -> #REF! | Q4: : | R4: =#REF! -> #REF!
C5: 2. | D5: =Ramp!B2 -> RAMP | H5: : | I5: =Ramp!H2 -> 4 | K5: 6. | L5: ='BRIDGE & NAVIGATION'!B2 -> BRIDGE & NAVIGATION ROOM | Q5: : | R5: ='BRIDGE & NAVIGATION'!H2 -> 4
C6: 3. | D6: =Accomodation!B2 -> ACCOMODATION | H6: : | I6: =Accomodation!H2 -> 4 | K6: 7. | L6: ='SHIP SAFETY OPERATION'!B2 -> SHIP SAFETY OPERATION | Q6: : | R6: ='SHIP SAFETY OPERATION'!H2 -> 4
C7: 4. | D7: =#REF! -> #REF! | H7: : | I7: =#REF! -> #REF!

Sheet EXECUTIVE SUMMARY - 3
C2: Breakdown Overall Rating
C4: 1. | D4: ='Hull & Cons'!B2 -> HULL & CONSTRUCTION OVERALL CAP RATING | H4: : | I4: ='Hull & Cons'!H2 -> 4 | K4: 5. | L4: =#REF! -> #REF! | Q4: : | R4: =#REF! -> #REF!
D5: - | E5: ='Hull & Cons'!B4 -> Hull | L5: - | M5: =#REF! -> #REF!
D6: - | E6: ='Hull & Cons'!B34 -> Construction | L6: - | M6: =#REF! -> #REF!
L7: - | M7: =#REF! -> #REF!
C8: 2. | D8: =Ramp!B2 -> RAMP | H8: : | I8: =Ramp!H2 -> 4 | L8: - | M8: =#REF! -> #REF!
D9: - | E9: =Ramp!B4 -> Fore Ramp | L9: - | M9: ='PUMP&PIPE - xx'!B3 -> Pump
D10: - | E10: =Ramp!B28 -> Bow Visor | L10: - | M10: ='PUMP&PIPE - xx'!B42 -> Pipe
D11: - | E11: =Ramp!B47 -> Aft Ramp
D12: - | E12: =Ramp!B71 -> Portside Ramp | K12: 6. | L12: ='BRIDGE & NAVIGATION'!B2 -> BRIDGE & NAVIGATION ROOM | Q12: : | R12: ='BRIDGE & NAVIGATION'!H2 -> 4
D13: - | E13: =Ramp!B95 -> Starboard Ramp | L13: - | M13: ='BRIDGE & NAVIGATION'!B4 -> General Condition
D14: - | E14: =Ramp!B119 -> In Ramp | L14: - | M14: ='BRIDGE & NAVIGATION'!B50 -> Navigation Equipment
L15: - | M15: ='BRIDGE & NAVIGATION'!B73 -> Communication Equipment
C16: 3. | D16: =Accomodation!B2 -> ACCOMODATION | H16: : | I16: =Accomodation!H2 -> 4 | L16: - | M16: ='BRIDGE & NAVIGATION'!B90 -> Navigation Light
D17: - | E17: =Accomodation!B4 -> Crew
D18: - | E18: =Accomodation!B41 -> Passenger | K18: 7. | L18: ='SHIP SAFETY OPERATION'!B2 -> SHIP SAFETY OPERATION | Q18: : | R18: ='SHIP SAFETY OPERATION'!H2 -> 4
L19: - | M19: ='SHIP SAFETY OPERATION'!B4 -> Operation Document
C20: 4. | D20: =#REF! -> #REF! | H20: : | I20: =#REF! -> #REF! | L20: - | M20: ='SHIP SAFETY OPERATION'!B54 -> Life Saving Appliance
D21: - | E21: =#REF! -> #REF! | L21: - | M21: ='SHIP SAFETY OPERATION'!B153 -> Fire Fighting Appliance
D22: - | E22: =#REF! -> #REF!

Sheet EXECUTIVE SUMMARY - 2
B2: 2 | D2: CONDITION | K2: =AVERAGE(J8,J12,J20,J24,T8,T16,T22) -> #REF!
E4: CAP
E5: 1 | F5: 2 | H5: 3 | J5: 4
C8: 1. | D8: ='Hull & Cons'!B2 -> HULL & CONSTRUCTION OVERALL CAP RATING | I8: : | J8: ='Hull & Cons'!H2 -> 4 | L8: 5. | M8: =#REF! -> #REF! | S8: : | T8: =#REF! -> #REF!
D9: - | E9: ='Hull & Cons'!B4 -> Hull | G9: : | H9: ='Hull & Cons'!H4 -> 4 | M9: - | N9: =#REF! -> #REF! | Q9: : | R9: =#REF! -> #REF!
D10: - | E10: ='Hull & Cons'!B34 -> Construction | G10: : | H10: ='Hull & Cons'!H34 -> 4 | M10: - | N10: =#REF! -> #REF! | Q10: : | R10: =#REF! -> #REF!
M11: - | N11: =#REF! -> #REF! | Q11: : | R11: =#REF! -> #REF!
C12: 2. | D12: =Ramp!B2 -> RAMP | I12: : | J12: =Ramp!H2 -> 4 | M12: - | N12: =#REF! -> #REF! | Q12: : | R12: =#REF! -> #REF!
D13: - | E13: =Ramp!B4 -> Fore Ramp | G13: : | H13: =Ramp!H4 -> 4 | M13: - | N13: ='PUMP&PIPE - xx'!B3 -> Pump | Q13: : | R13: ='PUMP&PIPE - xx'!I3 -> 2.5
D14: - | E14: =Ramp!B28 -> Bow Visor | G14: : | H14: =Ramp!H28 -> 4 | M14: - | N14: ='PUMP&PIPE - xx'!B42 -> Pipe | Q14: : | R14: ='PUMP&PIPE - xx'!I42 -> 1
D15: - | E15: =Ramp!B47 -> Aft Ramp | G15: : | H15: =Ramp!H47 -> 4
D16: - | E16: =Ramp!B71 -> Portside Ramp | G16: : | H16: =Ramp!H71 -> 4 | L16: 6. | M16: ='BRIDGE & NAVIGATION'!B2 -> BRIDGE & NAVIGATION ROOM | S16: : | T16: ='BRIDGE & NAVIGATION'!H2 -> 4
D17: - | E17: =Ramp!B95 -> Starboard Ramp | G17: : | H17: =Ramp!H95 -> 4 | M17: - | N17: ='BRIDGE & NAVIGATION'!B4 -> General Condition | Q17: : | R17: ='BRIDGE & NAVIGATION'!H4 -> 4
D18: - | E18: =Ramp!B119 -> In Ramp | G18: : | H18: =Ramp!H119 -> 4 | M18: - | N18: ='BRIDGE & NAVIGATION'!B50 -> Navigation Equipment | Q18: : | R18: ='BRIDGE & NAVIGATION'!H50 -> 4
M19: - | N19: ='BRIDGE & NAVIGATION'!B73 -> Communication Equipment | Q19: : | R19: ='BRIDGE & NAVIGATION'!H73 -> 4
C20: 3. | D20: =Accomodation!B2 -> ACCOMODATION | I20: : | J20: =Accomodation!H2 -> 4 | M20: - | N20: ='BRIDGE & NAVIGATION'!B90 -> Navigation Light | Q20: : | R20: ='BRIDGE & NAVIGATION'!H90 -> 4
D21: - | E21: =Accomodation!B4 -> Crew | G21: : | H21: =Accomodation!H4 -> 4
D22: - | E22: =Accomodation!B41 -> Passenger | G22: : | H22: =Accomodation!H41 -> 4 | L22: 7. | M22: ='SHIP SAFETY OPERATION'!B2 -> SHIP SAFETY OPERATION | S22: : | T22: ='SHIP SAFETY OPERATION'!H2 -> 4
M23: - | N23: ='SHIP SAFETY OPERATION'!B4 -> Operation Document | Q23: : | R23: ='SHIP SAFETY OPERATION'!H4 -> 4
C24: 4. | D24: =#REF! -> #REF! | I24: : | J24: =#REF! -> #REF! | M24: - | N24: ='SHIP SAFETY OPERATION'!B54 -> Life Saving Appliance | Q24: : | R24: ='SHIP SAFETY OPERATION'!H54 -> 2.1555556
D25: - | E25: =#REF! -> #REF! | G25: : | H25: =#REF! -> #REF! | M25: - | N25: ='SHIP SAFETY OPERATION'!B153 -> Fire Fighting Appliance | Q25: : | R25: ='SHIP SAFETY OPERATION'!H153 -> 4
D26: - | E26: =#REF! -> #REF! | G26: : | H26: =#REF! -> #REF!

Sheet Hull & Cons
A1: No. | B1: Item | H1: Overall CAP Rating
A2: I | B2: HULL & CONSTRUCTION OVERALL CAP RATING | H2: =AVERAGE(H4,H34) -> 4
A4: 1 | B4: Hull | H4: =AVERAGE(H5:H27) -> 4
B5: 46023 | D5: BOTTOM TOP/SIDE SHELL | H5: =AVERAGE(G7:G8) -> 4
E6: C | F6: V | G6: Avg
C7: a | D7: Plat Starboard Side | E7: 4 | F7: 4 | G7: =AVERAGE(E7:F7) -> 4
C8: b | D8: Plat Port Side | E8: 4 | F8: 4 | G8: =AVERAGE(E8:F8) -> 4
B9: Note:
B10: - | C10: (Lokasi temuan+kondisi kerusakan)
B11: - | C11: (Lokasi temuan+kondisi kerusakan)
B13: 46054 | D13: MARKS | H13: =AVERAGE(G15:G19) -> 4
E14: C | F14: V | G14: Avg
C15: a | D15: Plimsol | E15: 4 | F15: 4 | G15: =AVERAGE(E15:F15) -> 4
C16: b | D16: Draft | E16: 4 | F16: 4 | G16: =AVERAGE(E16:F16) -> 4
C17: c | D17: IMO Number | E17: 4 | F17: 4 | G17: =AVERAGE(E17:F17) -> 4
C18: d | D18: Ship Name | E18: 4 | F18: 4 | G18: =AVERAGE(E18:F18) -> 4
C19: e | D19: Tanda Selar | E19: 4 | F19: 4 | G19: =AVERAGE(E19:F19) -> 4
B20: Note:
B21: - | C21: (Lokasi temuan+kondisi kerusakan)
B22: - | C22: (Lokasi temuan+kondisi kerusakan)
B24: 1.3 | D24: FENDER | H24: =AVERAGE(G26:G28) -> 4
E25: C | F25: V | G25: Avg
C26: a | D26: Starboard Side | E26: 4 | F26: 4 | G26: =AVERAGE(E26:F26) -> 4
C27: b | D27: Port Side | E27: 4 | F27: 4 | G27: =AVERAGE(E27:F27) -> 4
C28: c | D28: Transom | E28: 4 | F28: 4 | G28: =AVERAGE(E28:F28) -> 4
B29: Note:
B30: - | C30: (Lokasi temuan+kondisi kerusakan)
B31: - | C31: (Lokasi temuan+kondisi kerusakan)
A34: 2 | B34: Construction | H34: =AVERAGE(H35:H54) -> 4
B35: 46024 | D35: CAR DECK | H35: =AVERAGE(G37:G39) -> 4
E36: C | F36: V | G36: Avg
C37: a | D37: Deck Plate | E37: 4 | F37: 4 | G37: =AVERAGE(E37:F37) -> 4
C38: b | D38: Inner Wall | E38: 4 | F38: 4 | G38: =AVERAGE(E38:F38) -> 4
C39: c | D39: Intermediate Deck | E39: 4 | F39: 4 | G39: =AVERAGE(E39:F39) -> 4
C40: e | D40: Lashing (D Ring, Belting, etc.) | E40: - | F40: 4 | G40: =AVERAGE(E40:F40) -> 4
B41: Note:
B42: - | C42: (Lokasi temuan+kondisi kerusakan)
B43: - | C43: (Lokasi temuan+kondisi kerusakan)
B45: 46055 | D45: SUPER STRUCTURE | H45: =AVERAGE(G47:G49) -> 4
E46: C | F46: V | G46: Avg
...

Sheet Ramp
A1: No. | B1: Item | H1: Overall CAP Rating
A2: II | B2: RAMP | H2: =AVERAGE(H4,H28,H47,H71,H95,H119) -> 4
A4: 1 | B4: Fore Ramp | H4: =AVERAGE(H5:H22) -> 4
B5: 46023 | D5: Construction | H5: =AVERAGE(G7:G9) -> 4
E6: C | F6: V | G6: Avg
C7: a | D7: Plate | E7: 4 | F7: 4 | G7: =AVERAGE(E7:F7) -> 4
C8: b | D8: Stanchion Roller | E8: 4 | F8: 4 | G8: =AVERAGE(E8:F8) -> 4
C9: c | D9: Structure (Web, Girder, Etc) | E9: 4 | F9: 4 | G9: =AVERAGE(E9:F9) -> 4
B10: Note:
B11: - | C11: (Lokasi temuan+kondisi kerusakan)
B12: - | C12: (Lokasi temuan+kondisi kerusakan)
B14: 46054 | D14: Lifting | H14: =AVERAGE(G16:G23) -> 4
E15: F | F15: V | G15: Avg
C16: a | D16: Pad Eye | E16: - | F16: 4 | G16: =AVERAGE(E16:F16) -> 4
C17: b | D17: Hinges | E17: 4 | F17: 4 | G17: =AVERAGE(E17:F17) -> 4
C18: c | D18: Roller | E18: 4 | F18: 4 | G18: =AVERAGE(E18:F18) -> 4
C19: d | D19: Wire | E19: - | F19: 4 | G19: =AVERAGE(E19:F19) -> 4
D20: Next Renewal date:
C21: e | D21: Chain Ramp | E21: - | F21: 4 | G21: =AVERAGE(E21:F21) -> 4
C22: f | D22: Stopper | E22: - | F22: 4 | G22: =AVERAGE(E22:F22) -> 4
C23: g | D23: Hydraulic Arm | E23: 4 | F23: 4 | G23: =AVERAGE(E23:F23) -> 4
B24: Note:
B25: - | C25: (Lokasi temuan+kondisi kerusakan)
B26: - | C26: (Lokasi temuan+kondisi kerusakan)
A28: 2 | B28: Bow Visor | H28: =AVERAGE(H29:H37) -> 4
B29: 46024 | D29: Cons | H29: =AVERAGE(G31:G32) -> 4
E30: C | F30: V | G30: Avg
C31: a | D31: Plate | E31: 4 | F31: 4 | G31: =AVERAGE(E31:F31) -> 4
C32: b | D32: Structure (Web, Girder, Etc) | E32: 4 | F32: 4 | G32: =AVERAGE(E32:F32) -> 4
B33: Note:
B34: - | C34: (Lokasi temuan+kondisi kerusakan)
B35: - | C35: (Lokasi temuan+kondisi kerusakan)
B37: 46055 | D37: Lifting | H37: =AVERAGE(G39:G42) -> 4
E38: F | F38: V | G38: Avg
C39: a | D39: Hinges | E39: - | F39: 4 | G39: =AVERAGE(E39:F39) -> 4
C40: b | D40: Roller | E40: 4 | F40: 4 | G40: =AVERAGE(E40:F40) -> 4
C41: c | D41: Hydraulic Arm | E41: 4 | F41: 4 | G41: =AVERAGE(E41:F41) -> 4
C42: d | D42: Stopper | E42: - | F42: 4 | G42: =AVERAGE(E42:F42) -> 4
B43: Note:
B44: - | C44: (Lokasi temuan+kondisi kerusakan)
...

Sheet Accomodation
B1: Item | H1: Overall CAP Rating
A2: III | B2: ACCOMODATION | H2: =AVERAGE(H4,H41) -> 4
A4: 1 | B4: Crew | H4: =AVERAGE(H5:H35) -> 4
B5: 46023 | D5: Master & Officer Room | H5: =AVERAGE(G7:G13) -> 4
F6: V | G6: Avg
C7: a | D7: Master Room | F7: 4 | G7: =AVERAGE(E7:F7) -> 4
C8: b | D8: Chief Engineer Room | F8: 4 | G8: =AVERAGE(E8:F8) -> 4
C9: c | D9: Chief Officer Room | F9: 4 | G9: =AVERAGE(E9:F9) -> 4
C10: d | D10: Toilet | F10: 4 | G10: =AVERAGE(E10:F10) -> 4
C11: e | D11: officer room | F11: 4 | G11: =AVERAGE(E11:F11) -> 4
C12: f | D12: office | F12: 4 | G12: =AVERAGE(E12:F12) -> 4
C13: g | D13: Lounge | F13: 4 | G13: =AVERAGE(E13:F13) -> 4
B14: Note:
B15: - | C15: (Lokasi temuan+kondisi kerusakan)
B16: - | C16: (Lokasi temuan+kondisi kerusakan)
B18: 46054 | D18: Crew Room | H18: =AVERAGE(G20:G25) -> 4
E19: F | F19: V | G19: Avg
C20: a | D20: Crew Room | E20: - | F20: 4 | G20: =AVERAGE(E20:F20) -> 4
C21: b | D21: Mess Room | E21: - | F21: 4 | G21: =AVERAGE(E21:F21) -> 4
C22: c | D22: Galley | E22: - | F22: 4 | G22: =AVERAGE(E22:F22) -> 4
C23: d | D23: Lounge Room | E23: - | F23: 4 | G23: =AVERAGE(E23:F23) -> 4
C24: e | D24: Laundry Room | E24: - | F24: 4 | G24: =AVERAGE(E24:F24) -> 4
C25: f | D25: Toilet/shower room | E25: 4 | F25: 4 | G25: =AVERAGE(E25:F25) -> 4
B26: Note:
B27: - | C27: (Lokasi temuan+kondisi kerusakan)
B28: - | C28: (Lokasi temuan+kondisi kerusakan)
B30: 1.3 | D30: Store | H30: =AVERAGE(G32:G35) -> 4
E31: F | F31: V | G31: Avg
C32: a | D32: Engine Store | E32: - | F32: 4 | G32: =AVERAGE(E32:F32) -> 4
C33: b | D33: Deck Store (Bosun,Paint,Etc) | E33: - | F33: 4 | G33: =AVERAGE(E33:F33) -> 4
C34: c | D34: Provision Store (Cold & Dry) | E34: 4 | F34: 4 | G34: =AVERAGE(E34:F34) -> 4
C35: d | D35: Safety Equipment Store | E35: - | F35: 4 | G35: =AVERAGE(E35:F35) -> 4
B36: Note:
B37: - | C37: (Lokasi temuan+kondisi kerusakan)
B38: - | C38: (Lokasi temuan+kondisi kerusakan)
A41: 2 | B41: Passenger | H41: =AVERAGE(H42:H77) -> 4
B42: 46024 | D42: Economy | H42: =AVERAGE(G44:G48) -> 4
E43: F | F43: V | G43: Avg
C44: a | D44: Pendingin ruangan | E44: 4 | F44: 4 | G44: =AVERAGE(E44:F44) -> 4
C45: b | D45: TV,Audio & Video | E45: 4 | F45: 4 | G45: =AVERAGE(E45:F45) -> 4
...

Sheet Deck Machinery & Outfitting
A1: No. | B1: Item | H1: Overall CAP Rating
A2: IV | B2: DECK MACHINERY & OUTFITTING OVERALL CAP RATING | H2: =AVERAGE(H4,H83) -> 4
A4: 1 | B4: Deck Machinery | H4: =AVERAGE(H5:H81) -> 4
B5: 46023 | D5: Hydraulic Pump for Mooring Winch/Windlass AFT | H5: =AVERAGE(G7:G12) -> 4
E6: C | F6: V | G6: Avg
C7: a | D7: Electro Motor | E7: 4 | F7: 4 | G7: =AVERAGE(E7:F7) -> 4
C8: b | D8: Pump | E8: 4 | F8: 4 | G8: =AVERAGE(E8:F8) -> 4
C9: c | D9: Control Valve | E9: 4 | F9: 4 | G9: =AVERAGE(E9:F9) -> 4
C10: d | D10: Hydraulic Hose | E10: 4 | F10: 4 | G10: =AVERAGE(E10:F10) -> 4
C11: e | D11: Pipe | E11: 4 | F11: 4 | G11: =AVERAGE(E11:F11) -> 4
C12: f | D12: Tank | E12: 4 | F12: 4 | G12: =AVERAGE(E12:F12) -> 4
B13: Note:
B14: - | C14: (Lokasi temuan+kondisi kerusakan)
B15: - | C15: (Lokasi temuan+kondisi kerusakan)
B17: 46054 | D17: Hydraulic Pump for Mooring Winch/Windlass Fore | H17: =AVERAGE(G19:G24) -> 4
E18: C | F18: V | G18: Avg
C19: a | D19: Electro Motor | E19: 4 | F19: 4 | G19: =AVERAGE(E19:F19) -> 4
C20: b | D20: Pump | E20: 4 | F20: 4 | G20: =AVERAGE(E20:F20) -> 4
C21: c | D21: Control Valve | E21: 4 | F21: 4 | G21: =AVERAGE(E21:F21) -> 4
C22: d | D22: Hydraulic Hose | E22: 4 | F22: 4 | G22: =AVERAGE(E22:F22) -> 4
C23: e | D23: Pipe | E23: 4 | F23: 4 | G23: =AVERAGE(E23:F23) -> 4
C24: f | D24: Tank | E24: 4 | F24: 4 | G24: =AVERAGE(E24:F24) -> 4
B25: Note:
B26: - | C26: (Lokasi temuan+kondisi kerusakan)
B27: - | C27: (Lokasi temuan+kondisi kerusakan)
B29: 1.3 | D29: Anchor and Rampdoor Winch/Windlass PS | H29: =AVERAGE(G31:G39) -> 4
F30: V | G30: Avg
C31: a | D31: Gipsy | F31: 4 | G31: =AVERAGE(E31:F31) -> 4
C32: b | D32: Redcution Gear | F32: 4 | G32: =AVERAGE(E32:F32) -> 4
C33: c | D33: Drum | F33: 4 | G33: =AVERAGE(E33:F33) -> 4
C34: d | D34: Clutch | F34: 4 | G34: =AVERAGE(E34:F34) -> 4
C35: e | D35: Control Stand | F35: 4 | G35: =AVERAGE(E35:F35) -> 4
C36: f | D36: Hand Break | F36: 4 | G36: =AVERAGE(E36:F36) -> 4
C37: g | D37: Actuator/Reduction Gear Box | F37: 4 | G37: =AVERAGE(E37:F37) -> 4
C38: h | D38: Construction | F38: 4 | G38: =AVERAGE(E38:F38) -> 4
C39: i | D39: Stopper | F39: 4 | G39: =AVERAGE(E39:F39) -> 4
B40: Note:
B41: - | C41: (Lokasi temuan+kondisi kerusakan)
B42: - | C42: (Lokasi temuan+kondisi kerusakan)
B44: 1.4 | D44: Anchor and Rampdoor Winch/Windlass SB | H44: =AVERAGE(G46:G54) -> 4
...

Sheet ER&Machinery-1
A1: No. | B1: Item | H1: Overall CAP Rating
A2: V | B2: ENGINE ROOM & MACHINERY OVERALL CAP RATING | H2: =AVERAGE(H4,H66,H110,H154,'ER&MAchinery-2'!I3,'ER&MAchinery-2'!I43) -> 4
A4: 1 | B4: General Condition | H4: =AVERAGE(H5:H64) -> 4
B5: 1.1 | D5: Engine Room | H5: =AVERAGE(G7:G20) -> 4
E6: F | F6: V | G6: Avg
C7: a | D7: Deck Plat | E7: - | F7: 4 | G7: =AVERAGE(E7:F7) -> 4
C8: b | D8: Stair | E8: - | F8: 4 | G8: =AVERAGE(E8:F8) -> 4
C9: c | D9: Bulkhead | E9: - | F9: 4 | G9: =AVERAGE(E9:F9) -> 4
C10: d | D10: Grating/Bordes | E10: - | F10: 4 | G10: =AVERAGE(E10:F10) -> 4
C11: e | D11: Sliding Door/Water Tight Door | E11: - | F11: 4 | G11: =AVERAGE(E11:F11) -> 4
C12: f | D12: Bottom Construction | E12: - | F12: 4 | G12: =AVERAGE(E12:F12) -> 4
C13: g | D13: Lighting | E13: 4 | F13: 4 | G13: =AVERAGE(E13:F13) -> 4
C14: h | D14: General/Fire Alarm | E14: 4 | F14: - | G14: =AVERAGE(E14:F14) -> 4
C15: i | D15: Emergency Telephone | E15: 4 | F15: - | G15: =AVERAGE(E15:F15) -> 4
C16: j | D16: CO2 Noozle | E16: 4 | F16: - | G16: =AVERAGE(E16:F16) -> 4
C17: k | D17: Smoke Detector | E17: 4 | F17: - | G17: =AVERAGE(E17:F17) -> 4
C18: l | D18: Escape Route | E18: - | F18: 4 | G18: =AVERAGE(E18:F18) -> 4
C19: m | D19: Insulation | E19: - | F19: 4 | G19: =AVERAGE(E19:F19) -> 4
C20: n | D20: Ducting | E20: - | F20: 4 | G20: =AVERAGE(E20:F20) -> 4
B21: Note:
B22: - | C22: (Lokasi temuan+kondisi kerusakan)
B23: - | C23: (Lokasi temuan+kondisi kerusakan)
B25: 1.2 | D25: Engine Control Room | H25: =AVERAGE(G27:G30) -> 4
E26: F | F26: V | G26: Avg
C27: a | D27: Engine Control Console | E27: 4 | F27: - | G27: =AVERAGE(E27:F27) -> 4
C28: b | D28: MSB (Manometer, Syncronize AE, Emgcy Shutdown) | E28: 4 | F28: - | G28: =AVERAGE(E28:F28) -> 4
C29: c | D29: Communication (Telephone/Radio) | E29: 4 | F29: - | G29: =AVERAGE(E29:F29) -> 4
C30: d | D30: Room | E30: - | F30: 4 | G30: =AVERAGE(E30:F30) -> 4
B31: Note:
B32: - | C32: (Lokasi temuan+kondisi kerusakan)
B33: - | C33: (Lokasi temuan+kondisi kerusakan)
B35: 1.3 | D35: Steering Room | H35: =AVERAGE(G37:G45) -> 4
E36: F | F36: V | G36: Avg
C37: a | D37: Deck Plat | E37: - | F37: 4 | G37: =AVERAGE(E37:F37) -> 4
C38: b | D38: Stair/Vertical Ladder | E38: - | F38: 4 | G38: =AVERAGE(E38:F38) -> 4
C39: c | D39: Bulkhead | E39: - | F39: 4 | G39: =AVERAGE(E39:F39) -> 4
C40: d | D40: Grating/Bordes | E40: - | F40: 4 | G40: =AVERAGE(E40:F40) -> 4
C41: e | D41: Lighting | E41: 4 | F41: - | G41: =AVERAGE(E41:F41) -> 4
C42: f | D42: General/Fire Alarm | E42: 4 | F42: - | G42: =AVERAGE(E42:F42) -> 4
C43: g | D43: Emergency Telephone | E43: 4 | F43: - | G43: =AVERAGE(E43:F43) -> 4
...

Sheet ER&MAchinery-2
A1: No. | B1: Item | I1: Overall CAP Rating
A3: 5 | B3: Pump | I3: =AVERAGE(H6:H38) -> 4
E4: F
E5: Motor | F5: Pump | G5: Panel | H5: Avg
B6: 1.1 | D6: FO Pump | E6: 4 | F6: 4 | G6: 4 | H6: =AVERAGE(E6:G6) -> 4
B7: 1.2 | D7: Fire Pump | E7: 4 | F7: 4 | G7: 4 | H7: =AVERAGE(E7:G7) -> 4
B8: 1.3 | D8: SW Air Cond. Pump | E8: 4 | F8: 4 | G8: 4 | H8: =AVERAGE(E8:G8) -> 4
B9: 1.4 | D9: Sewage Pump | E9: 4 | F9: 4 | G9: 4 | H9: =AVERAGE(E9:G9) -> 4
B10: 1.5 | D10: Emergency Bilge Pump | E10: 4 | F10: 4 | G10: 4 | H10: =AVERAGE(E10:G10) -> 4
B11: 1.6 | D11: Bilge Pump | E11: 4 | F11: 4 | G11: 4 | H11: =AVERAGE(E11:G11) -> 4
B12: 1.7 | D12: FW Press. Set. Pump | E12: 4 | F12: 4 | G12: 4 | H12: =AVERAGE(E12:G12) -> 4
B13: 1.8 | D13: GS / Fire Pump | E13: 4 | F13: 4 | G13: 4 | H13: =AVERAGE(E13:G13) -> 4
B14: 1.9 | D14: LO Priming Pump | E14: 4 | F14: 4 | G14: 4 | H14: =AVERAGE(E14:G14) -> 4
B15: 1.10 | D15: SW Pump | E15: 4 | F15: 4 | G15: 4 | H15: =AVERAGE(E15:G15) -> 4
B16: 1.11 | D16: LO Stbd Gear Box Pump 1&2 | E16: 4 | F16: 4 | G16: 4 | H16: =AVERAGE(E16:G16) -> 4
B17: 1.12 | D17: Emergency SW Cooling Pump | E17: 4 | F17: 4 | G17: 4 | H17: =AVERAGE(E17:G17) -> 4
... B23: 1.18 | D23: SW Press Set Pump 1&2 | E23: 4 | F23: 4 | G23: 4 | H23: =AVERAGE(E23:G23) -> 4
B24: 1.19 | D24: Oily Water Separator
F25: F | G25: V | H25: Avg
C26: a | D26: Bilge electric motor | F26: 4 | G26: 4 | H26: =AVERAGE(E26:G26) -> 4
C27: b | D27: Coalescer reservoir | F27: 4 | G27: 4 | H27: =AVERAGE(E27:G27) -> 4
C28: c | D28: Oil Discharge Monitoring ( ODM ) | F28: 4 | G28: 4 | H28: =AVERAGE(E28:G28) -> 4
C29: d | D29: Selenoid / safety device | F29: 4 | G29: 4 | H29: =AVERAGE(E29:G29) -> 4
B30: 1.20 | D30: Air Compressor
F31: F | G31: V | H31: Avg
C32: a | D32: Motor Engine | F32: 4 | G32: 4 | H32: =AVERAGE(E32:G32) -> 4
C33: b | D33: Bare pump | F33: 4 | G33: 4 | H33: =AVERAGE(E33:G33) -> 4
C34: c | D34: Safety Device | F34: 4 | G34: 4 | H34: =AVERAGE(E34:G34) -> 4
B35: 1.21 | D35: Air reservoir
F36: F | G36: V | H36: Avg
C37: a | D37: Contruction | F37: 4 | G37: 4 | H37: =AVERAGE(E37:G37) -> 4
C38: b | D38: Safety Valve / Pressure Valve | F38: 4 | G38: 4 | H38: =AVERAGE(E38:G38) -> 4
B39: Note:
B40: - | C40: (Lokasi temuan+kondisi kerusakan)
B41: - | C41: (Lokasi temuan+kondisi kerusakan)
A43: 6 | B43: Pipe | I43: =AVERAGE(H46:H50) -> 4
E44: F
E45: Pipe | F45: Valve | G45: Flange | H45: Avg
B46: 2.1 | D46: FO Pipe & Valve | E46: 4 | F46: 4 | G46: 4 | H46: =AVERAGE(E46:G46) -> 4
D47: LO Pipe & Valve | E47: 4 | F47: 4 | G47: 4 | H47: =AVERAGE(E47:G47) -> 4
...

Sheet PUMP&PIPE - xx
A3: 5 | B3: Pump | I3: =AVERAGE(I6,I7,I8,I9,I10,I11,I12,I13,I14,I15,I16,I17,I18,I19,I20,I21,I22,I23,I24,I30,I35) -> 2.5
E4: F | O4: Fuel Oil Consumption
E5: MOTOR | F5: PUMP | G5: PANEL | H5: AVG | O5: No | P5: Item | Q5: Idle | S5: Slow | U5: Service | W5: Full
B6: 5.1 | D6: FO Pump | E6: 3 | F6: 3 | G6: 3 | Q6: speed | R6: foc | S6: speed | T6: foc | U6: speed | V6: foc | W6: speed | X6: foc
B7: 5.2 | D7: Fire Pump | O7: 1 | P7: ME PS
B8: 5.3 | D8: SW Air Cond. Pump | O8: 2 | P8: ME SB
B9: 5.4 | D9: Sewage Pump | O9: 3 | P9: AE 1
B10: 5.5 | D10: Emergency Bilge Pump | O10: 4 | P10: AE 2
B11: 5.6 | D11: Bilge Pump | O11: 5 | P11: AE 3
B12: 5.7 | D12: FW Press. Set. Pump
B13: 5.8 | D13: GS / Fire Pump
B14: 5.9 | D14: LO Priming Pump
B15: 5.10 | D15: SW Pump
B16: 5.11 | D16: LO Stbd Gear Box Pump 1&2
B17: 5.12 | D17: Emergency SW Cooling Pump
B18: 5.13 | D18: FO Transfer Pump
B19: 5.14 | D19: LO Transfer Pump 1&2
B20: 5.15 | D20: ME FW Cooling Pump
B21: 5.16 | D21: Dirty Oil Pump
B22: 5.17 | D22: Ballast Pump 1&2
B23: 5.18 | D23: SW Press Set Pump 1&2
B24: 5.19 | D24: Oily Water Separator | I24: =AVERAGE(H26:H28) -> 2.5
E25: F | F25: V | H25: Avg
C26: a | D26: Bilge electric motor | E26: 2 | F26: 3 | H26: =AVERAGE(E26:F26) -> 2.5
C27: b | D27: Coalescer reservoir | E27: 2 | F27: 3 | H27: =AVERAGE(E27:F27) -> 2.5
C28: c | D28: Oil Discharge Monitoring ( ODM ) | E28: 2 | F28: 3 | H28: =AVERAGE(E28:F28) -> 2.5
C29: d | D29: Selenoid / safety device
B30: 5.20 | D30: Air Compressor | I30: =AVERAGE(H32:H34) -> 2.5
E31: F | F31: V | H31: Avg
C32: a | D32: Motor Engine | E32: 2 | F32: 3 | H32: =AVERAGE(E32:F32) -> 2.5
C33: b | D33: Bare pump | E33: 2 | F33: 3 | H33: =AVERAGE(E33:F33) -> 2.5
C34: c | D34: Safety Device | E34: 2 | F34: 3 | H34: =AVERAGE(E34:F34) -> 2.5
B35: 5.21 | D35: Air reservoir | I35: =AVERAGE(H37:H39) -> 2.5
E36: F | F36: V | H36: Avg
C37: a | D37: Contruction | E37: 2 | F37: 3 | H37: =AVERAGE(E37:F37) -> 2.5
C38: b | D38: Safety Valve / Pressure Valve | E38: 2 | F38: 3 | H38: =AVERAGE(E38:F38) -> 2.5
C39: c | E39: 2 | F39: 3 | H39: =AVERAGE(E39:F39) -> 2.5
B40: Note | C40: : | D40: Posisi Kerusakan
A42: 7 | B42: Pipe | I42: =AVERAGE(H45:H49) -> 1
E43: F
...

Sheet BRIDGE & NAVIGATION
A1: No. | B1: Item | H1: Overall CAP Rating
A2: VI | B2: BRIDGE & NAVIGATION ROOM | H2: =AVERAGE(H4,H50,H73,H90) -> 4
A4: 1 | B4: General Condition | H4: =AVERAGE(H5,H26,H38) -> 4
B5: 46023 | D5: Navigation Room | H5: =AVERAGE(G7:G21) -> 4
E6: F | F6: V | G6: Avg
C7: a | D7: Floor | E7: - | F7: 4 | G7: =AVERAGE(E7:F7) -> 4
C8: b | D8: Ceiling/plafon | E8: - | F8: 4 | G8: =AVERAGE(E8:F8) -> 4
C9: c | D9: Window | E9: - | F9: 4 | G9: =AVERAGE(E9:F9) -> 4
C10: d | D10: Bridge Control Panel | E10: 4 | F10: - | G10: =AVERAGE(E10:F10) -> 4
C11: e | D11: Engine Telegraph | E11: 4 | F11: - | G11: =AVERAGE(E11:F11) -> 4
C12: f | D12: Weather Tight Door | E12: 4 | F12: 4 | G12: =AVERAGE(E12:F12) -> 4
C13: g | D13: Lighting | E13: 4 | F13: 4 | G13: =AVERAGE(E13:F13) -> 4
C14: h | D14: General/Fire Alarm | E14: 4 | F14: - | G14: =AVERAGE(E14:F14) -> 4
C15: i | D15: Smoke Detector | E15: 4 | F15: - | G15: =AVERAGE(E15:F15) -> 4
C16: j | D16: Clear View Screen | E16: 4 | F16: - | G16: =AVERAGE(E16:F16) -> 4
D17: Qty:
C18: k | D18: Wiper | E18: 4 | F18: - | G18: =AVERAGE(E18:F18) -> 4
D19: Qty:
C20: l | D20: Public Adressor | E20: 4 | F20: - | G20: =AVERAGE(E20:F20) -> 4
C21: m | D21: Toilet | E21: 4 | F21: 4 | G21: =AVERAGE(E21:F21) -> 4
B22: Note:
B23: - | C23: (Lokasi temuan+kondisi kerusakan)
B24: - | C24: (Lokasi temuan+kondisi kerusakan)
B26: 1.2 | D26: Radio Room | H26: =AVERAGE(G28:G33) -> 4
E27: F | F27: V | G27: Avg
C28: a | D28: Floor | E28: - | F28: 4 | G28: =AVERAGE(E28:F28) -> 4
C29: b | D29: Ceiling/plafon | E29: - | F29: 4 | G29: =AVERAGE(E29:F29) -> 4
C30: c | D30: Window | E30: - | F30: 4 | G30: =AVERAGE(E30:F30) -> 4
C31: d | D31: Lighting | E31: 4 | F31: 4 | G31: =AVERAGE(E31:F31) -> 4
C32: e | D32: Smoke Detector | E32: 4 | F32: - | G32: =AVERAGE(E32:F32) -> 4
C33: f | D33: CCTV Monitor | E33: 4 | F33: - | G33: =AVERAGE(E33:F33) -> 4
B34: Note:
B35: - | C35: (Lokasi temuan+kondisi kerusakan)
B36: - | C36: (Lokasi temuan+kondisi kerusakan)
B38: 1.3 | D38: Equipment | H38: =AVERAGE(G40:G44) -> 4
F39: F | G39: Avg
D40: Binocular | F40: 4 | G40: =AVERAGE(E40:F40) -> 4
D41: Qty:
D42: Barometer | F42: 4 | G42: =AVERAGE(E42:F42) -> 4
D43: Temperature Gauge | F43: 4 | G43: =AVERAGE(E43:F43) -> 4
...

Sheet NAV - Inventroy
A1: Navigation & Communication Equipment
A2: No. | B2: Item | E2: Qty | G2: Specification
B3: Navigation Equipment
A4: 1 | B4: Radar
A5: 2 | B5: GPS
A6: 3 | B6: Echosounder
A7: 4 | B7: Anemometer
A8: 5 | B8: AIS
A9: 6 | B9: Gyro Compass
A10: 7 | B10: Magnetic Compass
A11: 8 | B11: ECDIS
A12: 9 | B12: Autopilot
A13: 10 | B13: Steering Wheel
A14: 11 | B14: Bow Thruster Control Stand
A15: 12 | B15: Throttle
... A17: 14 | B17: BNWAS
B18: Communication Equipment
A19: 1 | B19: Navtex Receiver
A20: 2 | B20: GMDSS
A21: 3 | B21: MF/HF
A22: 4 | B22: VHF
A23: 5 | B23: Handy Talky
A24: 6 | B24: Public Adressor
A25: 7 | B25: Sound Power Telephone
A26: 8 | B26: Electrical/Air Horn
A27: 9 | B27: Weather Fax
A28: 10 | B28: Inmarsat

Sheet SHIP SAFETY OPERATION
A1: No. | B1: Item | H1: Overall CAP Rating
A2: VII | B2: SHIP SAFETY OPERATION | H2: =AVERAGE(H153,H4) -> 4
A4: 1 | B4: Operation Document | H4: =AVERAGE(H5:H49) -> 4
B5: 46023 | D5: Class Certificate | H5: =AVERAGE(G7:G16) -> 4
F6: M | G6: Avg
C7: a | D7: International Load Line Certificate | F7: 4 | G7: =AVERAGE(E7:F7) -> 4
D8: Date issued:
D9: Exp:
C10: b | D10: Certificate of Classification for Hull | F10: 4 | G10: =AVERAGE(E10:F10) -> 4
D11: Date issued:
D12: Exp:
C13: c | D13: Certificate of Classification for Machinery | F13: 4 | G13: =AVERAGE(E13:F13) -> 4
D14: Date issued:
D15: Exp:
C16: d | D16: Wreck Removal Certificate | F16: 4 | G16: =AVERAGE(E16:F16) -> 4
D17: Date issued:
D18: Exp:
B20: 1.2 | D20: Statutory Certificate | H20: =AVERAGE(G22:G49) -> 4
F21: M | G21: Avg
C22: a | D22: Surat Laut (Certificate of Nationality) | F22: 4 | G22: =AVERAGE(E22:F22) -> 4
D23: Date issued:
C24: b | D24: Gross Akta | F24: 4 | G24: =AVERAGE(E24:F24) -> 4
D25: Date issued:
C26: c | D26: Surat Ukur Internasional (International Tonnage Certificate) | F26: 4 | G26: =AVERAGE(E26:F26) -> 4
D27: Date issued:
C28: d | D28: SKKP (Sertifikat Keselamatan Kapal Penumpang) | F28: 4 | G28: =AVERAGE(E28:F28) -> 4
D29: Date issued:
D30: Exp:
C31: e | D31: Minimum Safe Manning Document | F31: 4 | G31: =AVERAGE(E31:F31) -> 4
D32: Date issued:
D33: Exp:
C34: f | D34: Document of Compliance | F34: 4 | G34: =AVERAGE(E34:F34) -> 4
D35: Date issued:
D36: Exp:
C37: g | D37: Safety Management Certificate | F37: 4 | G37: =AVERAGE(E37:F37) -> 4
D38: Date issued:
D39: Exp:
C40: h | D40: Sertifikat Nasional Pencegahan Pencemaran (SNPP) | F40: 4 | G40: =AVERAGE(E40:F40) -> 4
D41: Date issued:
D42: Exp:
...

Sheet Copy of ER&M
B1: ENGINE ROOM & MACHINERY | H1: =AVERAGE(H2,H20,#REF!,#REF!,#REF!) -> #REF!
A2: 1 | B2: GENERAL CONDITION | H2: =AVERAGE(H3:H48) -> 3
B3: 46023 | D3: Engine Room | H3: =AVERAGE(G5:G7) -> 3
E4: F | F4: V | G4: Avg
C5: a | D5: Deck Plat | E5: 3 | F5: 3 | G5: =AVERAGE(E5:F5) -> 3
C6: b | D6: Stair | E6: 3 | F6: 3 | G6: =AVERAGE(E6:F6) -> 3
C7: c | D7: Bulkhead | E7: 3 | F7: 3 | G7: =AVERAGE(E7:F7) -> 3
C8: d | D8: Grating/Bordes
C9: e | D9: Sliding Door/Water Tight Door
C10: f | D10: Bottom Construction
C11: g | D11: Lighting
C12: h | D12: General/Fire Alarm
C13: i | D13: Emergency Telephone
C14: j | D14: Sprinkle
C15: k | D15: Smoke Detector
C16: l | D16: Escape Route
C17: m | D17: Insulation
C18: n | D18: Ducting
B20: 1.2 | D20: Engine Control Room | H20: =AVERAGE(G22:G24) -> 3
E21: F | F21: V | G21: Avg
C22: a | D22: Engine Control Console | E22: 3 | F22: 3 | G22: =AVERAGE(E22:F22) -> 3
C23: b | D23: MSB (Manometer, Syncronize AE, Emgcy Shutdown) | E23: 3 | F23: 3 | G23: =AVERAGE(E23:F23) -> 3
C24: c | D24: Communication (Telephone/Radio) | E24: 3 | F24: 3 | G24: =AVERAGE(E24:F24) -> 3
C25: d | D25: Room
B27: 1.2 | D27: Steering Room | H27: =AVERAGE(G29:G47) -> 3
E28: F | F28: V | G28: Avg
C29: a | D29: Deck Plat | E29: 3 | F29: 3 | G29: =AVERAGE(E29:F29) -> 3
C30: b | D30: Stair/Vertical Ladder | E30: 3 | F30: 3 | G30: =AVERAGE(E30:F30) -> 3
C31: c | D31: Bulkhead | E31: 3 | F31: 3 | G31: =AVERAGE(E31:F31) -> 3
C32: d | D32: Grating/Bordes
C33: e | D33: Lighting
C34: f | D34: General/Fire Alarm
C35: g | D35: Emergency Telephone
C36: h | D36: Smoke Detector
C37: i | D37: Ducting
B39: 1.2 | D39: Bow Thruster Room | H39: =AVERAGE(G41:G71) -> 3
E40: F | F40: V | G40: Avg
C41: a | D41: Deck Plat | E41: 3 | F41: 3 | G41: =AVERAGE(E41:F41) -> 3
C42: b | D42: Stair/Vertical Ladder | E42: 3 | F42: 3 | G42: =AVERAGE(E42:F42) -> 3
C43: c | D43: Bulkhead | E43: 3 | F43: 3 | G43: =AVERAGE(E43:F43) -> 3
...

Sheet LSA FFA - Inventory
A1: Life Saving Appliance & Fire Fighting Appliance Equipment
A2: No. | B2: Item | G2: Qty
B3: Life Saving Appliance Equipment
A4: 1 | B4: HRU
A5: 2 | B5: ILR
A6: 3 | B6: Life Line Throwing
A7: 4 | B7: Rocket Parachute
A8: 5 | B8: Smoke Signal
A9: 6 | B9: Hand Flare
A10: 7 | B10: EEBD (Emergency Escape Breathing Device)
A11: 8 | B11: EPIRB (Emergency Position-Indicating Radio Beacon)
A12: 9 | B12: SART (Search and Rescue Transponder)
A13: 10 | B13: Life Buoy with Line or Light
A14: 11 | B14: Life Jacket
A15: 12 | B15: Rescue Boat
... A18: 15 | B18: Muster Station
B19: Fire Fighting Appliance Equipment
A20: 1 | B20: Portable CO2 Fire Extinghuisher
A21: 2 | B21: Portable Foam Fire Extinghuisher
A22: 3 | B22: Fire Box, Hose, and Nozzle
A23: 4 | B23: Fire Blanket
A24: 5 | B24: Fireman Outfit
A25: 6 | B25: SOPEP
A26: 7 | B26: SCBA (Self-Contained Breathing Apparatus)
A27: 8 | B27: Smoke Detector
A28: 9 | B28: Heat Detector
A29: 10 | B29: Sprinkle
A30: 11 | B30: Emergency Fire Pump
A31: 12 | B31: Hydrant
... A33: 14 | B33: International Shore Connection
